Workbook

Sheet Service Report
K1: Max/Minumum | M1: Formula + | N1: Sum
A2: Sr Number | B2: Date | C2: Customer Name | D2: Brand | E2: Product | F2: Problems | G2: Warranty Status | H2: Customer Type | I2: Location | J2: Delivery Date | K2: Service Charges | L2: Paid | M2: Pending | N2: Total | O2: Status | P2: Service Engineer | Q2: Remark
A3: 1 | B3: 44205 | C3: Sandhya Waghmare | D3: LG | E3: LG Washing Machine | F3: Washing machine not starting | G3: Warranty | H3: New | I3: Swargate | J3: 44205 | K3: 0 | L3: 0 | M3: =IF(K3="0",0,K3-L3) -> 0 | N3: =L3+M3 -> 0 | O3: Completed | P3: Anket | Q3: =IF(L3=0,"Paid","Pending") -> Paid
A4: 2 | B4: 44205 | C4: Ketan Kanojia | D4: Whirlpool | E4: Whirpool refrigerator | F4: Buildup of Frost in the Ice Dispenser | G4: Warranty | H4: Exisitng | I4: Kothrud | J4: 44205 | K4: 3000 | L4: 2000 | M4: =IF(K4="0",0,K4-L4) -> 1000 | N4: =L4+M4 -> 3000 | O4: In Progress | P4: Mannu | Q4: =IF(L4=0,"Paid","Pending") -> Pending
A5: 3 | B5: 44205 | C5: Sanket Gaikwad | D5: Samsung | E5: Samsung Refrigerator | F5: Sensors are not working | G5: Warranty | H5: New | I5: Camp | J5: 44236 | K5: 5000 | L5: 3000 | M5: =IF(K5="0",0,K5-L5) -> 2000 | N5: =L5+M5 -> 5000 | O5: In Progress | P5: Suchit | Q5: =IF(L5=0,"Paid","Pending") -> Pending
A6: 4 | B6: 44205 | C6: Vidhya Bhagat | D6: Samsung | E6: Samsung LED | F6: TV won't power up but the power light blinks | G6: Non Warranty | H6: New | I6: Aundh | J6: 44236 | K6: 0 | L6: 0 | M6: =IF(K6="0",0,K6-L6) -> 0 | N6: =L6+M6 -> 0 | O6: Completed | P6: Moha | Q6: =IF(L6=0,"Paid","Pending") -> Paid
A7: 5 | B7: 44236 | C7: Kavita Gawhale | D7: Godrej | E7: Godrej Washing Machine | F7: Washing machine not spinning | G7: Non Warranty | H7: New | I7: Bhavani peth | J7: 44264 | K7: 2000 | L7: 2000 | M7: =IF(K7="0",0,K7-L7) -> 0 | N7: =L7+M7 -> 2000 | O7: Completed | P7: Karan | Q7: =IF(L7=0,"Paid","Pending") -> Pending
A8: 6 | B8: 44236 | C8: Mrunal Badade | D8: Blue star | E8: Bluestar AC | F8: Air Conditioner Not Blowing Cold Air | G8: Non Warranty | H8: New | I8: Katraj | J8: 44264 | K8: 500 | L8: 500 | M8: =IF(K8="0",0,K8-L8) -> 0 | N8: =L8+M8 -> 500 | O8: Completed | P8: Furqan | Q8: =IF(L8=0,"Paid","Pending") -> Pending
A9: 7 | B9: 44236 | C9: Laxmi Itenwar | D9: Blue star | E9: Bluestar AC | F9: Air Conditioner Not Blowing Cold Air | G9: Warranty | H9: New | I9: Swargate | J9: 44295 | K9: 0 | L9: 0 | M9: =IF(K9="0",0,K9-L9) -> 0 | N9: =L9+M9 -> 0 | O9: In Progress | P9: Anket | Q9: =IF(L9=0,"Paid","Pending") -> Paid
A10: 8 | B10: 44264 | C10: Mohammad Aryan Kazi | D10: Samsung | E10: Samsung Refrigerator | F10: Freezer Isn't Cold Enough | G10: Warranty | H10: New | I10: Aundh | J10: 44295 | K10: 600 | L10: 600 | M10: =IF(K10="0",0,K10-L10) -> 0 | N10: =L10+M10 -> 600 | O10: In Progress | P10: Mannu | Q10: =IF(L10=0,"Paid","Pending") -> Pending
A11: 9 | B11: 44264 | C11: Om Karve | D11: Samsung | E11: Samsung Refrigerator | F11: Buildup of Frost in the Ice Dispenser | G11: Non Warranty | H11: Exisitng | I11: Viman nagar | J11: 44295 | K11: 0 | M11: =IF(K11="0",0,K11-L11) -> 0 | N11: =L11+M11 -> 0 | O11: In Progress | P11: Suchit | Q11: =IF(L11=0,"Paid","Pending") -> Paid
A12: 10 | B12: 44386 | C12: DIVYA AMARPRATAP GUPTA | D12: Whirlpool | E12: Whirpool refrigerator | F12: Freezer Isn't Cold Enough | G12: Non Warranty | H12: Exisitng | I12: Aundh | J12: 44295 | K12: 600 | L12: 600 | M12: =IF(K12="0",0,K12-L12) -> 0 | N12: =L12+M12 -> 600 | O12: Completed | P12: Moha | Q12: =IF(L12=0,"Paid","Pending") -> Pending
A13: 11 | B13: 44386 | C13: ABHISHEK JITENDRA DUMDE | D13: Blue star | E13: Bluestar AC | F13: Air Conditioner Freezing Up Outside Unit | G13: Warranty | H13: New | I13: Pimple Saudagar | J13: 44448 | K13: 0 | M13: =IF(K13="0",0,K13-L13) -> 0 | N13: =L13+M13 -> 0 | O13: In Progress | P13: Karan | Q13: =IF(L13=0,"Paid","Pending") -> Paid
A14: 12 | B14: 44386 | C14: JYOTI MACHINDRA DAKE | D14: Blue star | E14: Bluestar AC | F14: AC Refrigerant Leak | G14: Warranty | H14: Exisitng | I14: Warje | J14: 44448 | K14: 500 | L14: 0 | M14: =IF(K14="0",0,K14-L14) -> 500 | N14: =L14+M14 -> 500 | O14: Completed | P14: Furqan | Q14: =IF(L14=0,"Paid","Pending") -> Paid
A15: 13 | B15: 44478 | C15: ROHIT DYANDEV RITOND | D15: Samsung | E15: Samsung LED | F15: TV has sound but no picture | G15: Non Warranty | H15: New | I15: Warje | J15: 44509 | K15: 0 | L15: 0 | M15: =IF(K15="0",0,K15-L15) -> 0 | N15: =L15+M15 -> 0 | O15: Completed | P15: Suchit | Q15: =IF(L15=0,"Paid","Pending") -> Paid
A16: 14 | B16: 44509 | C16: TWINKLE SUNIL KHONDE | D16: Samsung | E16: Samsung LED | F16: TV has sound but no picture | G16: Warranty | H16: Exisitng | I16: Viman Nagar | J16: 15/9/2021 | K16: 1000 | L16: 0 | M16: =IF(K16="0",0,K16-L16) -> 1000 | N16: =L16+M16 -> 1000 | O16: In Progress | P16: Moha | Q16: =IF(L16=0,"Paid","Pending") -> Paid
A17: 15 | B17: 44509 | C17: SHEETAL SHIVA ARAVANTI | D17: Samsung | E17: Samsung LED | F17: TV has a picture, but no sound | G17: Non Warranty | H17: Exisitng | I17: Swargate | J17: 15/9/2021 | K17: 2000 | L17: 1000 | M17: =IF(K17="0",0,K17-L17) -> 1000 | N17: =L17+M17 -> 2000 | O17: Completed | P17: Karan | Q17: =IF(L17=0,"Paid","Pending") -> Pending
A18: 16 | B18: 44509 | C18: KIRTI DHANANJAY KHADE | D18: Samsung | E18: Samsung LED | F18: TV has a picture, but no sound | G18: Warranty | H18: Exisitng | I18: Bhavani Peth | J18: 15/9/2021 | K18: 4000 | L18: 2000 | M18: =IF(K18="0",0,K18-L18) -> 2000 | N18: =L18+M18 -> 4000 | O18: Completed | P18: Suchit | Q18: =IF(L18=0,"Paid","Pending") -> Pending
A19: 17 | B19: 44509 | C19: ASHWINI BHARAT GAIKWAD | D19: Samsung | E19: Samsung Refrigerator | F19: Fresh Food Compartment Is Warming Up | G19: Non Warranty | H19: New | I19: Aundh | J19: 16/9/2021 | K19: 3000 | L19: 2000 | M19: =IF(K19="0",0,K19-L19) -> 1000 | N19: =L19+M19 -> 3000 | O19: Completed | P19: Moha | Q19: =IF(L19=0,"Paid","Pending") -> Pending
A20: 18 | B20: 14/9/2021 | C20: OMKAR PRAKASH WALUNJ | D20: Samsung | E20: Samsung Refrigerator | F20: Fresh Food Compartment Is Warming Up | G20: Non Warranty | H20: Exisitng | I20: Swargate | J20: 16/9/2021 | K20: 3000 | L20: 3000 | M20: =IF(K20="0",0,K20-L20) -> 0 | N20: =L20+M20 -> 3000 | O20: In Progress | P20: Karan | Q20: =IF(L20=0,"Paid","Pending") -> Pending
A21: 19 | B21: 14/9/2021 | C21: JYOTI SHIVRAJ TODALGE | D21: Blue star | E21: Bluestar AC | F21: Air Conditioner Making Noises | G21: Warranty | H21: Exisitng | I21: Aundh | J21: 16/9/2021 | K21: 2000 | L21: 2000 | M21: =IF(K21="0",0,K21-L21) -> 0 | N21: =L21+M21 -> 2000 | O21: Hand over to Customer | P21: Anket | Q21: =IF(L21=0,"Paid","Pending") -> Pending
A22: 20 | B22: 14/9/2021 | C22: Varsha Sunil Shelar | D22: Blue star | E22: Bluestar AC | F22: Frozen Evaporator Coil | G22: Warranty | H22: New | I22: Pimple Saudagar | J22: 16/9/2021 | K22: 1000 | L22: 1000 | M22: =IF(K22="0",0,K22-L22) -> 0 | N22: =L22+M22 -> 1000 | O22: Hand over to Customer | P22: Mannu | Q22: =IF(L22=0,"Paid","Pending") -> Pending
A23: 21 | B23: 15/9/2021 | C23: Shameem Ajij Shaikh | D23: Blue star | E23: Bluestar AC | F23: Air Conditioner Making Noises | G23: Warranty | H23: Exisitng | I23: Swargate | J23: 16/9/2021 | K23: 0 | L23: 0 | M23: =IF(K23="0",0,K23-L23) -> 0 | N23: =L23+M23 -> 0 | O23: Hand over to Customer | P23: Suchit | Q23: =IF(L23=0,"Paid","Pending") -> Paid
A24: 22 | B24: 15/9/2021 | C24: Swapnali Ramdas Choudhari | D24: Samsung | E24: Samsung LED | F24: TV has a picture, but no sound | G24: Warranty | H24: New | I24: Kothrud | J24: 16/9/2021 | K24: 0 | L24: 0 | M24: =IF(K24="0",0,K24-L24) -> 0 | N24: =L24+M24 -> 0 | O24: Parts are not available | P24: Moha | Q24: =IF(L24=0,"Paid","Pending") -> Paid
A25: 23 | B25: 15/9/2021 | C25: Amit Bhati | D25: LG | E25: LG Washing Machine | F25: Excessive vibrations during operation | G25: Non Warranty | H25: New | I25: Camp | J25: 16/9/2021 | K25: 1000 | L25: 500 | M25: =IF(K25="0",0,K25-L25) -> 500 | N25: =L25+M25 -> 1000 | O25: Parts are not available | P25: Anket | Q25: =IF(L25=0,"Paid","Pending") -> Pending
A26: 24 | B26: 16/9/2021 | C26: Nihal Kisan Kamble | D26: Whirlpool | E26: Whirpool refrigerator | F26: Freezer Isn't Cold Enough | G26: Non Warranty | H26: Exisitng | I26: Aundh | J26: 18/9/2021 | K26: 2000 | L26: 1500 | M26: =IF(K26="0",0,K26-L26) -> 500 | N26: =L26+M26 -> 2000 | O26: In Progress | P26: Anket | Q26: =IF(L26=0,"Paid","Pending") -> Pending
A27: 25 | B27: 16/9/2021 | C27: Akshata Naresh Shete | D27: Samsung | E27: Samsung Refrigerator | F27: Buildup of Frost in the Ice Dispenser | G27: Non Warranty | H27: Exisitng | I27: Bhavani peth | J27: 18/9/2021 | K27: 4000 | L27: 500 | M27: =IF(K27="0",0,K27-L27) -> 3500 | N27: =L27+M27 -> 4000 | O27: In Progress | P27: Mannu | Q27: =IF(L27=0,"Paid","Pending") -> Pending
A28: 26 | B28: 17/9/2021 | C28: Abu Adnan Shaikh | D28: Samsung | E28: Samsung LED | F28: TV won't power up but the power light blinks | G28: Warranty | H28: Exisitng | I28: Katraj | J28: 18/9/2021 | K28: 3000 | L28: 3000 | M28: =IF(K28="0",0,K28-L28) -> 0 | N28: =L28+M28 -> 3000 | O28: Parts are not available | P28: Mannu | Q28: =IF(L28=0,"Paid","Pending") -> Pending
A29: 27 | B29: 17/9/2021 | C29: Deepak gaikwad | D29: Godrej | E29: Godrej Washing Machine | F29: Washing machine is noisy. | G29: Non Warranty | H29: Exisitng | I29: Swargate | J29: 18/9/2021 | K29: 3000 | L29: 3000 | M29: =IF(K29="0",0,K29-L29) -> 0 | N29: =L29+M29 -> 3000 | O29: In Progress | P29: Mannu | Q29: =IF(L29=0,"Paid","Pending") -> Pending
A30: 28 | B30: 17/9/2021 | C30: Kanchan Gaikwad | D30: Blue star | E30: Bluestar AC | F30: Frozen Evaporator Coil | G30: Warranty | H30: New | I30: Aundh | J30: 18/9/2021 | K30: 2000 | L30: 500 | M30: =IF(K30="0",0,K30-L30) -> 1500 | N30: =L30+M30 -> 2000 | O30: Completed | P30: Anket | Q30: =IF(L30=0,"Paid","Pending") -> Pending
A31: 29 | B31: 18/9/2021 | C31: Naushin Ahmed | D31: Blue star | E31: Bluestar AC | F31: Air Conditioner Making Noises | G31: Warranty | H31: New | I31: Viman nagar | J31: 21/9/2021 | K31: 1000 | L31: 500 | M31: =IF(K31="0",0,K31-L31) -> 500 | N31: =L31+M31 -> 1000 | O31: Hand over to Customer | P31: Mannu | Q31: =IF(L31=0,"Paid","Pending") -> Pending
... A42: 40 | B42: 28/9/2021 | C42: Afrin Nadaf | D42: Samsung | E42: Samsung LED | F42: TV flickers and turns off suddenly | G42: Warranty | H42: Exisitng | I42: Aundh | J42: 23/9/2021 | K42: 3000 | L42: 1000 | M42: =IF(K42="0",0,K42-L42) -> 2000 | N42: =L42+M42 -> 3000 | O42: In Progress | P42: Karan | Q42: =IF(L42=0,"Paid","Pending") -> Pending
M43: Total | N43: =L43+M43 -> #VALUE! | Q43: =IF(L43=0,"Paid","Pending") -> Paid

Sheet Sales Report
B1: Name of Customer | C1: Customer Id | D1: Location | E1: Mobile No. | F1: Order Date | G1: Order Time | H1: Items | I1: Item's Code | J1: Quantity | K1: Unit Price | L1: Total Price | M1: Delivery Date | N1: Delivery Time | O1: Remarks
A2: 1 | B2: Mahesh Jain | C2: AK-Clothes-2324 | D2: Bengaluru | E2: ********45 | F2: 44228 | G2: 11:30am | H2: White Shirt | I2: PS2345 | J2: 2 | K2: 559 | L2: =J2*K2 -> 1118 | M2: 15/2/2021 | N2: 06:07pm | O2: Completed
A3: 2 | B3: Nidhi Agarwal | C3: AK-Clothes-2311 | D3: Mumbai | E3: ********89 | F3: 44229 | G3: 12:07pm | H3: Lehenga Saree | I3: SQ2388 | J3: 1 | K3: 3399 | L3: =J3*K3 -> 3399 | M3: 16/2/2021 | N3: 09:00am | O3: In Process
A4: 3 | B4: Kunal Anand | C4: AK-Clothes-3200 | D4: Pune | E4: ********67 | F4: 44230 | G4: 02:56pm | H4: Denim Jeans | I4: ZE6777 | J4: 2 | K4: 789 | L4: =J4*K4 -> 1578 | M4: 17/2/2021 | N4: 09:30am | O4: Completed
A5: 4 | B5: Ajay Kulkarni | C5: AK-Clothes-3125 | D5: Pune | E5: ********22 | F5: 44231 | G5: 01:23pm | H5: T-Shirts | I5: AS4545 | J5: 3 | K5: 499 | L5: =J5*K5 -> 1497 | M5: 18/2/2021 | N5: 07:00pm | O5: Completed
A6: 5 | B6: Suhas Reddy | C6: AK-Clothes-2328 | D6: Chennai | E6: ********31 | F6: 44232 | G6: 08:00am | H6: Black Trouser | I6: XC7777 | J6: 2 | K6: 1999 | L6: =J6*K6 -> 3998 | M6: 19/2/2021 | N6: 04:50pm | O6: Completed
A7: 6 | B7: Priyanka Arya | C7: AK-Clothes-2320 | D7: Jaipur | E7: ********34 | F7: 44233 | G7: 05:44pm | H7: Floral Lehenga | I7: TH2321 | J7: 1 | K7: 2999 | L7: =J7*K7 -> 2999 | M7: 20/2/2021 | N7: 02:43pm | O7: Completed
A8: 7 | B8: Paromita Banerjee | C8: AK-Clothes-2777 | D8: Kolkata | E8: ********67 | F8: 44234 | G8: 11:11am | H8: Silk Saree | I8: QR6789 | J8: 2 | K8: 2599 | L8: =J8*K8 -> 5198 | M8: 21/2/2021 | N8: 11:30am | O8: Completed
A9: 8 | B9: Pooja Sharma | C9: AK-Clothes-2344 | D9: Bengaluru | E9: ********12 | F9: 44235 | G9: 07:00pm | H9: Banarasi Saree | I9: ZQ4422 | J9: 2 | K9: 2899 | L9: =J9*K9 -> 5798 | M9: 22/2/2021 | N9: 12:07pm | O9: Completed
A10: 9 | B10: Mohit Babu | C10: AK-Clothes-2867 | D10: Bengaluru | E10: ********60 | F10: 44236 | G10: 04:50pm | H10: Leather jacket | I10: ZQ3434 | J10: 1 | K10: 4999 | L10: =J10*K10 -> 4999 | M10: 23/2/2021 | N10: 02:56pm | O10: Completed
A11: 10 | B11: Praney Tiwari | C11: AK-Clothes-2940 | D11: Ahemdabad | E11: ********88 | F11: 44237 | G11: 02:43pm | H11: Denim Jeans | I11: MN4400 | J11: 1 | K11: 789 | L11: =J11*K11 -> 789 | M11: 24/2/2021 | N11: 01:23pm | O11: Completed
A12: 11 | B12: Suraj Solanki | C12: AK-Clothes-2334 | D12: Jaipur | E12: ********09 | F12: 44238 | G12: 01:22pm | H12: Olive Blazer | I12: PS5555 | J12: 1 | K12: 2999 | L12: =J12*K12 -> 2999 | M12: 25/2/2021 | N12: 08:00am | O12: Completed
A13: 12 | B13: Priyanka Agarwal | C13: AK-Clothes-2555 | D13: Mumbai | E13: ********30 | F13: 44239 | G13: 06:07pm | H13: Floral Saree | I13: FM5555 | J13: 2 | K13: 2299 | L13: =J13*K13 -> 4598 | M13: 26/2/2021 | N13: 05:44pm | O13: Completed
A14: 13 | B14: Saniya Shaikh | C14: AK-Clothes-2301 | D14: Indore | E14: ********57 | F14: 13/2/2021 | G14: 09:00am | H14: Silk Kurtas set | I14: PS2340 | J14: 1 | K14: 3299 | L14: =J14*K14 -> 3299 | M14: 27/2/2021 | N14: 11:11am | O14: Completed
A15: 14 | B15: Anita Chowdhary | C15: AK-Clothes-2098 | D15: Jaipur | E15: ********11 | F15: 14/2/2021 | G15: 09:30am | H15: Lehenga Saree | I15: SQ2311 | J15: 1 | K15: 3399 | L15: =J15*K15 -> 3399 | M15: 28/2/2021 | N15: 07:00pm | O15: Completed
A16: 15 | B16: Anisha Tiwari | C16: AK-Clothes-2312 | D16: Noida | E16: ********44 | F16: 15/2/2021 | G16: 07:00pm | H16: Lehenga Saree | I16: ZE6744 | J16: 1 | K16: 3399 | L16: =J16*K16 -> 3399 | M16: 44256 | N16: 04:50pm | O16: Completed
A17: 16 | B17: Zara khan | C17: AK-Clothes-3211 | D17: Mumbai | E17: ********63 | F17: 16/2/2021 | G17: 04:50pm | H17: Silk Kurtas Set | I17: AS4540 | J17: 1 | K17: 3299 | L17: =J17*K17 -> 3299 | M17: 44257 | N17: 02:43pm | O17: Completed
A18: 17 | B18: Priya Shukla | C18: AK-Clothes-1239 | D18: Jaipur | E18: ********27 | F18: 17/2/2021 | G18: 02:43pm | H18: Chikankari Kurti | I18: XQ1212 | J18: 4 | K18: 599 | L18: =J18*K18 -> 2396 | M18: 44258 | N18: 01:22pm | O18: Completed
A19: 18 | B19: Sunita Mishra | C19: AK-Clothes-2341 | D19: Delhi | E19: ********40 | F19: 18/2/2021 | G19: 11:30pm | H19: Banarasi Saree | I19: Mk4545 | J19: 2 | K19: 2899 | L19: =J19*K19 -> 5798 | M19: 44259 | N19: 11:30am | O19: Completed
A20: 19 | B20: Anjali shah | C20: AK-Clothes-1111 | D20: Kolkata | E20: ********92 | F20: 19/2/2021 | G20: 12:07pm | H20: Floral Saree | I20: ZQ2367 | J20: 2 | K20: 2299 | L20: =J20*K20 -> 4598 | M20: 44260 | N20: 12:07pm | O20: Completed
A21: 20 | B21: Anuj Pawar | C21: AK-Clothes-2300 | D21: Mumbai | E21: ********86 | F21: 20/2/2021 | G21: 02:56pm | H21: Black Blazer | I21: DK3490 | J21: 1 | K21: 2889 | L21: =J21*K21 -> 2889 | M21: 44261 | N21: 02:56pm | O21: Completed
A22: 21 | B22: Amey Jaiswal | C22: AK-Clothes-2342 | D22: Bengaluru | E22: ********81 | F22: 21/2/2021 | G22: 01:23pm | H22: Leather jacket | I22: AQ6565 | J22: 1 | K22: 4999 | L22: =J22*K22 -> 4999 | M22: 44262 | N22: 01:23pm | O22: Completed
A23: 22 | B23: Kunal Gaikwad | C23: AK-Clothes-1200 | D23: Surat | E23: ********12 | F23: 22/2/2021 | G23: 08:00am | H23: Denim jacket | I23: ZQ1393 | J23: 1 | K23: 1599 | L23: =J23*K23 -> 1599 | M23: 44263 | N23: 08:00am | O23: Completed
A24: 23 | B24: Smita Prakash | C24: AK-Clothes-2346 | D24: Jaipur | E24: ********96 | F24: 23/2/2021 | G24: 10:55am | H24: Lehenga Saree | I24: JS5678 | J24: 1 | K24: 3399 | L24: =J24*K24 -> 3399 | M24: 44264 | N24: 10:55am | O24: Completed
A25: 24 | B25: Anita Parikh | C25: AK-Clothes-2341 | D25: Mumbai | E25: ********90 | F25: 24/2/2021 | G25: 11:35am | H25: Silk Saree | I25: QQ3409 | J25: 3 | K25: 2599 | L25: =J25*K25 -> 7797 | M25: 44265 | N25: 11:35am | O25: Completed
A26: 25 | B26: Rahul Jaiswal | C26: AK-Clothes-2340 | D26: Indore | E26: ********95 | F26: 25/2/2021 | G26: 01:00pm | H26: Denim jacket | I26: ZQ2362 | J26: 1 | K26: 1599 | L26: =J26*K26 -> 1599 | M26: 44266 | N26: 01:00pm | O26: Completed
A27: 26 | B27: Sunita Sharma | C27: AK-Clothes-2349 | D27: Jaipur | E27: ********08 | F27: 26/2/2021 | G27: 08:00am | H27: Anarkali set | I27: DK3493 | J27: 1 | K27: 2599 | L27: =J27*K27 -> 2599 | M27: 44267 | N27: 08:00am | O27: In Process
A28: 27 | B28: Vishakha Soni | C28: AK-Clothes-2354 | D28: Noida | E28: ********10 | F28: 27/2/2021 | G28: 07:45am | H28: Lehenga Saree | I28: AQ6522 | J28: 1 | K28: 3399 | L28: =J28*K28 -> 3399 | M28: 13/3/2021 | N28: 07:45am | O28: In Process
A29: 28 | B29: Anup Prasad | C29: AK-Clothes-2321 | D29: Mumbai | E29: ********89 | F29: 28/2/2021 | G29: 11:11am | H29: T-Shirts | I29: ZQ1392 | J29: 3 | K29: 499 | L29: =J29*K29 -> 1497 | M29: 14/3/2021 | N29: 11:11am | O29: In Process
A30: 29 | B30: Vaibhavi Anand | C30: AK-Clothes-3292 | D30: Jaipur | E30: ********59 | F30: 44256 | G30: 07:00pm | H30: Chikankari Kurti | I30: JS5674 | J30: 3 | K30: 599 | L30: =J30*K30 -> 1797 | M30: 15/3/2021 | N30: 07:00pm | O30: In Process
A31: 30 | B31: Vishakha Rahi | C31: AK-Clothes-3203 | D31: Delhi | E31: ********94 | F31: 44257 | G31: 04:25pm | H31: Banarasi Saree | I31: QQ3411 | J31: 1 | K31: 2899 | L31: =J31*K31 -> 2899 | M31: 16/3/2021 | N31: 12:07pm | O31: In Process
A32: 31 | B32: Anuja Pathak | C32: AK-Clothes-3124 | D32: Kolkata | E32: ********97 | F32: 44258 | G32: 11:30pm | H32: Anarkali set | I32: SQ2382 | J32: 2 | K32: 2599 | L32: =J32*K32 -> 5198 | M32: 17/3/2021 | N32: 02:56pm | O32: In Process
A33: 32 | B33: Priti Pawar | C33: AK-Clothes-2325 | D33: Mumbai | E33: ********98 | F33: 44259 | G33: 12:07pm | H33: Floral Lehenga | I33: ZE6773 | J33: 1 | K33: 2999 | L33: =J33*K33 -> 2999 | M33: 18/3/2021 | N33: 01:23pm | O33: In Process
A34: 33 | B34: Usha Joshi | C34: AK-Clothes-2326 | D34: Chennai | E34: ********99 | F34: 44260 | G34: 02:56pm | H34: Floral Saree | I34: AS4544 | J34: 1 | K34: 2299 | L34: =J34*K34 -> 2299 | M34: 19/3/2021 | N34: 08:00am | O34: In Process
A35: 34 | B35: Namrata Rathi | C35: AK-Clothes-2778 | D35: Delhi | E35: ********11 | F35: 44261 | G35: 01:23pm | H35: Silk Saree | I35: XC7775 | J35: 2 | K35: 2599 | L35: =J35*K35 -> 5198 | M35: 20/3/2021 | N35: 10:55am | O35: In Process
A36: 35 | B36: Vijay Salvi | C36: AK-Clothes-2349 | D36: Ahemdabad | E36: ********81 | F36: 44262 | G36: 08:00am | H36: White Shirt | I36: TH2326 | J36: 2 | K36: 559 | L36: =J36*K36 -> 1118 | M36: 21/3/2021 | N36: 11:35am | O36: In Process
A37: 36 | B37: Sidhika Rahi | C37: AK-Clothes-2810 | D37: Noida | E37: ********10 | F37: 44263 | G37: 07:45am | H37: Lehenga Saree | I37: QR6787 | J37: 1 | K37: 3399 | L37: =J37*K37 -> 3399 | M37: 22/3/2021 | N37: 01:00pm | O37: In Process
A38: 37 | B38: Dev Banerjee | C38: AK-Clothes-2913 | D38: Kolkata | E38: ********13 | F38: 44264 | G38: 11:11am | H38: Olive Blazer | I38: ZQ4428 | J38: 1 | K38: 2999 | L38: =J38*K38 -> 2999 | M38: 23/3/2021 | N38: 08:00am | O38: In Process
A39: 38 | B39: Rushi Yadav | C39: AK-Clothes-2358 | D39: Noida | E39: ********24 | F39: 44265 | G39: 07:00pm | H39: Black Blazer | I39: ZQ3439 | J39: 1 | K39: 2889 | L39: =J39*K39 -> 2889 | M39: 24/3/2021 | N39: 07:45am | O39: In Process
A40: 39 | B40: Riya Sharma | C40: AK-Clothes-2523 | D40: Noida | E40: ********18 | F40: 44266 | G40: 04:50pm | H40: Chikankari Kurti | I40: MN4411 | J40: 3 | K40: 599 | L40: =J40*K40 -> 1797 | M40: 25/3/2021 | N40: 11:11am | O40: In Process
...

Sheet V-Lookup Result
B4: Name of Customer | C4: Remarks | D4: Items | E4: Total Price | F4: Delivery Date
B5: Pooja Sharma | C5: =VLOOKUP(B5,CHOOSE({1,2,3,4,5},'Sales Report'!$B:$B,'Sales Report'!$O:$O,'Sales Report'!$H:$H,'Sales Report'!$L:$L,'Sales Report'!$M:$M),2,0) -> Completed | D5: =VLOOKUP(B5,CHOOSE({1,2,3,4,5},'Sales Report'!$B:$B,'Sales Report'!$O:$O,'Sales Report'!$H:$H,'Sales Report'!$L:$L,'Sales Report'!$M:$M),3,0) -> Banarasi Saree | E5: =VLOOKUP(B5,CHOOSE({1,2,3,4,5},'Sales Report'!$B:$B,'Sales Report'!$O:$O,'Sales Report'!$H:$H,'Sales Report'!$L:$L,'Sales Report'!$M:$M),4,0) -> 5798 | F5: =VLOOKUP(B5,CHOOSE({1,2,3,4,5},'Sales Report'!$B:$B,'Sales Report'!$O:$O,'Sales Report'!$H:$H,'Sales Report'!$L:$L,'Sales Report'!$M:$M),5,0) -> 22/2/2021
B6: Zara khan | C6: =VLOOKUP(B6,CHOOSE({1,2,3,4,5},'Sales Report'!$B:$B,'Sales Report'!$O:$O,'Sales Report'!$H:$H,'Sales Report'!$L:$L,'Sales Report'!$M:$M),2,0) -> Completed | D6: =VLOOKUP(B6,CHOOSE({1,2,3,4,5},'Sales Report'!$B:$B,'Sales Report'!$O:$O,'Sales Report'!$H:$H,'Sales Report'!$L:$L,'Sales Report'!$M:$M),3,0) -> Silk Kurtas Set | E6: =VLOOKUP(B6,CHOOSE({1,2,3,4,5},'Sales Report'!$B:$B,'Sales Report'!$O:$O,'Sales Report'!$H:$H,'Sales Report'!$L:$L,'Sales Report'!$M:$M),4,0) -> 3299 | F6: =VLOOKUP(B6,CHOOSE({1,2,3,4,5},'Sales Report'!$B:$B,'Sales Report'!$O:$O,'Sales Report'!$H:$H,'Sales Report'!$L:$L,'Sales Report'!$M:$M),5,0) -> 44257
B7: Sunita Sharma | C7: =VLOOKUP(B7,CHOOSE({1,2,3,4,5},'Sales Report'!$B:$B,'Sales Report'!$O:$O,'Sales Report'!$H:$H,'Sales Report'!$L:$L,'Sales Report'!$M:$M),2,0) -> In Process | D7: =VLOOKUP(B7,CHOOSE({1,2,3,4,5},'Sales Report'!$B:$B,'Sales Report'!$O:$O,'Sales Report'!$H:$H,'Sales Report'!$L:$L,'Sales Report'!$M:$M),3,0) -> Anarkali set | E7: =VLOOKUP(B7,CHOOSE({1,2,3,4,5},'Sales Report'!$B:$B,'Sales Report'!$O:$O,'Sales Report'!$H:$H,'Sales Report'!$L:$L,'Sales Report'!$M:$M),4,0) -> 2599 | F7: =VLOOKUP(B7,CHOOSE({1,2,3,4,5},'Sales Report'!$B:$B,'Sales Report'!$O:$O,'Sales Report'!$H:$H,'Sales Report'!$L:$L,'Sales Report'!$M:$M),5,0) -> 44267
B8: Vijay Salvi | C8: =VLOOKUP(B8,CHOOSE({1,2,3,4,5},'Sales Report'!$B:$B,'Sales Report'!$O:$O,'Sales Report'!$H:$H,'Sales Report'!$L:$L,'Sales Report'!$M:$M),2,0) -> In Process | D8: =VLOOKUP(B8,CHOOSE({1,2,3,4,5},'Sales Report'!$B:$B,'Sales Report'!$O:$O,'Sales Report'!$H:$H,'Sales Report'!$L:$L,'Sales Report'!$M:$M),3,0) -> White Shirt | E8: =VLOOKUP(B8,CHOOSE({1,2,3,4,5},'Sales Report'!$B:$B,'Sales Report'!$O:$O,'Sales Report'!$H:$H,'Sales Report'!$L:$L,'Sales Report'!$M:$M),4,0) -> 1118 | F8: =VLOOKUP(B8,CHOOSE({1,2,3,4,5},'Sales Report'!$B:$B,'Sales Report'!$O:$O,'Sales Report'!$H:$H,'Sales Report'!$L:$L,'Sales Report'!$M:$M),5,0) -> 21/3/2021
B9: Riya Sharma | C9: =VLOOKUP(B9,CHOOSE({1,2,3,4,5},'Sales Report'!$B:$B,'Sales Report'!$O:$O,'Sales Report'!$H:$H,'Sales Report'!$L:$L,'Sales Report'!$M:$M),2,0) -> In Process | D9: =VLOOKUP(B9,CHOOSE({1,2,3,4,5},'Sales Report'!$B:$B,'Sales Report'!$O:$O,'Sales Report'!$H:$H,'Sales Report'!$L:$L,'Sales Report'!$M:$M),3,0) -> Chikankari Kurti | E9: =VLOOKUP(B9,CHOOSE({1,2,3,4,5},'Sales Report'!$B:$B,'Sales Report'!$O:$O,'Sales Report'!$H:$H,'Sales Report'!$L:$L,'Sales Report'!$M:$M),4,0) -> 1797 | F9: =VLOOKUP(B6,CHOOSE({1,2,3,4,5},'Sales Report'!$B:$B,'Sales Report'!$O:$O,'Sales Report'!$H:$H,'Sales Report'!$L:$L,'Sales Report'!$M:$M),5,0) -> 44257
B10: Praney Ahuja | C10: =VLOOKUP(B10,CHOOSE({1,2,3,4,5},'Sales Report'!$B:$B,'Sales Report'!$O:$O,'Sales Report'!$H:$H,'Sales Report'!$L:$L,'Sales Report'!$M:$M),2,0) -> In Process | D10: =VLOOKUP(B10,CHOOSE({1,2,3,4,5},'Sales Report'!$B:$B,'Sales Report'!$O:$O,'Sales Report'!$H:$H,'Sales Report'!$L:$L,'Sales Report'!$M:$M),3,0) -> Denim jacket | E10: =VLOOKUP(B10,CHOOSE({1,2,3,4,5},'Sales Report'!$B:$B,'Sales Report'!$O:$O,'Sales Report'!$H:$H,'Sales Report'!$L:$L,'Sales Report'!$M:$M),4,0) -> 1599 | F10: =VLOOKUP(B7,CHOOSE({1,2,3,4,5},'Sales Report'!$B:$B,'Sales Report'!$O:$O,'Sales Report'!$H:$H,'Sales Report'!$L:$L,'Sales Report'!$M:$M),5,0) -> 44267

Sheet COUNTIF
B2: Location | C2: Number of orders count
B3: Bengaluru | C3: =COUNTIF('Sales Report'!$D:$D,COUNTIF!B3) -> 4
B4: Mumbai | C4: =COUNTIF('Sales Report'!$D:$D,COUNTIF!B4) -> 10
B5: Pune | C5: =COUNTIF('Sales Report'!$D:$D,COUNTIF!B5) -> 2
B6: Chennai | C6: =COUNTIF('Sales Report'!$D:$D,COUNTIF!B6) -> 3
B7: Jaipur | C7: =COUNTIF('Sales Report'!$D:$D,COUNTIF!B7) -> 7
B8: Kolkata | C8: =COUNTIF('Sales Report'!$D:$D,COUNTIF!B8) -> 5
B9: Ahemdabad | C9: =COUNTIF('Sales Report'!$D:$D,COUNTIF!B9) -> 3

Sheet Conditional FormatingHighlights
B1: Customer Name | C1: Name of Customer
B2: Sandhya Waghmare | C2: Mahesh Jain
B3: Ketan Kanojia | C3: Nidhi Agarwal
B4: Sanket Gaikwad | C4: Kunal Anand
B5: Vidhya Bhagat | C5: Ajay Kulkarni
B6: Kavita Gawhale | C6: Suhas Reddy
B7: Mrunal Badade | C7: Priyanka Arya
B8: Laxmi Itenwar | C8: Paromita Banerjee
B9: Mohammad Aryan Kazi | C9: Pooja Sharma
B10: Om Karve | C10: Mohit Babu
B11: DIVYA AMARPRATAP GUPTA | C11: Praney Tiwari
B12: ABHISHEK JITENDRA DUMDE | C12: Suraj Solanki
... B41: Afrin Nadaf | C41: Sunita Pathak
C42: Uday Banerjee
C43: Vijay Shinde
C44: Sidhika Rai
C45: Devika Banerjee
C46: Rushi soni
C47: Omkar Ghode
C48: Sunita Modi
C49: Anshuman tiwari
C50: Praney Ahuja
C51: Anu Shah

Sheet Questions
B2: There are two sheets Sales and Service reports on each question I have marked the reference report. | C2: Marks
B3: 1- Column K replaces "warranty" with 0 . (Service Report) | C3: DONE
B4: 2- Calculate pending amount? By using formula. (Service Report) | C4: DONE
B5: 3- sum column N by using sum formula to get total (Service Report) | C5: DONE
B6: 4- Sheet 2 & 3 Use V-lookup to get the outcome for mentioned details. (Sales Report) | C6: DONE
B7: 5- Use Count-if to get the number of orders from each city mentioned as count if in a sheet. like Bangalore, Mumbai etc. (Sales Report) | C7: DONE | E7: =COUNTIF('Sales Report'!D2:D51,'Sales Report'!D2) -> 4
B8: 6- What is the maximum value/price (Price column K) of an item we have sold and it is in which cities. (Sales Report) | C8: DONE | D8: =MAX('Sales Report'!K2:K51) -> 4999 | E8: {=_xlfn._xlws.FILTER('Sales Report'!D2:D51,'Sales Report'!K2:K51=MAX('Sales Report'!K2:K51))} -> Bengaluru
B9: 7- What is the maximum value item we have sold (use formula to get). (Sales Report) | C9: =INDEX('Sales Report'!H:H,MATCH(MAX('Sales Report'!L:L),'Sales Report'!L:L,0)) -> Banarasi Saree | E9: Bengaluru
B10: 8- What is the total sales or revenue generated by a company ? (Sales Report). | C10: =SUMIF('Sales Report'!O:O,"Completed",'Sales Report'!L:L) -> 84041 | E10: Kolkata
B11: 9- column L (Total Price) uses formula, if i change the quantity then it must change the total price, so replace with formula. (Sales Report) | C11: DONE
B12: 10- highlight the status completed. (Service Report) | C12: DONE
B13: 11- There are few names that are duplicated or repeated in column B that use a function to highlight those names. (Highlight Name) | C13: DONE
